============================= test session starts ==============================
platform linux -- Python 3.12.1, pytest-8.4.1, pluggy-1.6.0 -- /workspaces/AUDITORIA360/.venv/bin/python3
cachedir: .pytest_cache
rootdir: /workspaces/AUDITORIA360
plugins: asyncio-1.1.0, anyio-4.9.0, playwright-0.7.0, base-url-2.1.0, mock-3.14.1
asyncio: mode=Mode.STRICT, asyncio_default_fixture_loop_scope=None, asyncio_default_test_loop_scope=function
collecting ... collected 220 items / 7 errors

==================================== ERRORS ====================================
______________ ERROR collecting portal_demandas/tests/test_api.py ______________
.venv/lib/python3.12/site-packages/sqlalchemy/engine/base.py:145: in __init__
    self._dbapi_connection = engine.raw_connection()
                             ^^^^^^^^^^^^^^^^^^^^^^^
.venv/lib/python3.12/site-packages/sqlalchemy/engine/base.py:3297: in raw_connection
    return self.pool.connect()
           ^^^^^^^^^^^^^^^^^^^
.venv/lib/python3.12/site-packages/sqlalchemy/pool/base.py:449: in connect
    return _ConnectionFairy._checkout(self)
           ^^^^^^^^^^^^^^^^^^^^^^^^^^^^^^^^
.venv/lib/python3.12/site-packages/sqlalchemy/pool/base.py:1264: in _checkout
    fairy = _ConnectionRecord.checkout(pool)
            ^^^^^^^^^^^^^^^^^^^^^^^^^^^^^^^^
.venv/lib/python3.12/site-packages/sqlalchemy/pool/base.py:713: in checkout
    rec = pool._do_get()
          ^^^^^^^^^^^^^^
.venv/lib/python3.12/site-packages/sqlalchemy/pool/impl.py:179: in _do_get
    with util.safe_reraise():
.venv/lib/python3.12/site-packages/sqlalchemy/util/langhelpers.py:224: in __exit__
    raise exc_value.with_traceback(exc_tb)
.venv/lib/python3.12/site-packages/sqlalchemy/pool/impl.py:177: in _do_get
    return self._create_connection()
           ^^^^^^^^^^^^^^^^^^^^^^^^^
.venv/lib/python3.12/site-packages/sqlalchemy/pool/base.py:390: in _create_connection
    return _ConnectionRecord(self)
           ^^^^^^^^^^^^^^^^^^^^^^^
.venv/lib/python3.12/site-packages/sqlalchemy/pool/base.py:675: in __init__
    self.__connect()
.venv/lib/python3.12/site-packages/sqlalchemy/pool/base.py:901: in __connect
    with util.safe_reraise():
.venv/lib/python3.12/site-packages/sqlalchemy/util/langhelpers.py:224: in __exit__
    raise exc_value.with_traceback(exc_tb)
.venv/lib/python3.12/site-packages/sqlalchemy/pool/base.py:897: in __connect
    self.dbapi_connection = connection = pool._invoke_creator(self)
                                         ^^^^^^^^^^^^^^^^^^^^^^^^^^
.venv/lib/python3.12/site-packages/sqlalchemy/engine/create.py:646: in connect
    return dialect.connect(*cargs, **cparams)
           ^^^^^^^^^^^^^^^^^^^^^^^^^^^^^^^^^^
.venv/lib/python3.12/site-packages/sqlalchemy/engine/default.py:625: in connect
    return self.loaded_dbapi.connect(*cargs, **cparams)  # type: ignore[no-any-return]  # NOQA: E501
           ^^^^^^^^^^^^^^^^^^^^^^^^^^^^^^^^^^^^^^^^^^^^
.venv/lib/python3.12/site-packages/psycopg2/__init__.py:122: in connect
    conn = _connect(dsn, connection_factory=connection_factory, **kwasync)
           ^^^^^^^^^^^^^^^^^^^^^^^^^^^^^^^^^^^^^^^^^^^^^^^^^^^^^^^^^^^^^^^
E   psycopg2.OperationalError: connection to server at "localhost" (::1), port 5432 failed: Connection refused
E   	Is the server running on that host and accepting TCP/IP connections?
E   connection to server at "localhost" (127.0.0.1), port 5432 failed: Connection refused
E   	Is the server running on that host and accepting TCP/IP connections?

The above exception was the direct cause of the following exception:
portal_demandas/tests/test_api.py:3: in <module>
    from portal_demandas.api import app
portal_demandas/api.py:5: in <module>
    from portal_demandas.db import SessionLocal, TicketDB
portal_demandas/db.py:23: in <module>
    Base.metadata.create_all(bind=engine)
.venv/lib/python3.12/site-packages/sqlalchemy/sql/schema.py:5924: in create_all
    bind._run_ddl_visitor(
.venv/lib/python3.12/site-packages/sqlalchemy/engine/base.py:3247: in _run_ddl_visitor
    with self.begin() as conn:
/home/codespace/.python/current/lib/python3.12/contextlib.py:137: in __enter__
    return next(self.gen)
           ^^^^^^^^^^^^^^
.venv/lib/python3.12/site-packages/sqlalchemy/engine/base.py:3237: in begin
    with self.connect() as conn:
         ^^^^^^^^^^^^^^
.venv/lib/python3.12/site-packages/sqlalchemy/engine/base.py:3273: in connect
    return self._connection_cls(self)
           ^^^^^^^^^^^^^^^^^^^^^^^^^^
.venv/lib/python3.12/site-packages/sqlalchemy/engine/base.py:147: in __init__
    Connection._handle_dbapi_exception_noconnection(
.venv/lib/python3.12/site-packages/sqlalchemy/engine/base.py:2436: in _handle_dbapi_exception_noconnection
    raise sqlalchemy_exception.with_traceback(exc_info[2]) from e
.venv/lib/python3.12/site-packages/sqlalchemy/engine/base.py:145: in __init__
    self._dbapi_connection = engine.raw_connection()
                             ^^^^^^^^^^^^^^^^^^^^^^^
.venv/lib/python3.12/site-packages/sqlalchemy/engine/base.py:3297: in raw_connection
    return self.pool.connect()
           ^^^^^^^^^^^^^^^^^^^
.venv/lib/python3.12/site-packages/sqlalchemy/pool/base.py:449: in connect
    return _ConnectionFairy._checkout(self)
           ^^^^^^^^^^^^^^^^^^^^^^^^^^^^^^^^
.venv/lib/python3.12/site-packages/sqlalchemy/pool/base.py:1264: in _checkout
    fairy = _ConnectionRecord.checkout(pool)
            ^^^^^^^^^^^^^^^^^^^^^^^^^^^^^^^^
.venv/lib/python3.12/site-packages/sqlalchemy/pool/base.py:713: in checkout
    rec = pool._do_get()
          ^^^^^^^^^^^^^^
.venv/lib/python3.12/site-packages/sqlalchemy/pool/impl.py:179: in _do_get
    with util.safe_reraise():
.venv/lib/python3.12/site-packages/sqlalchemy/util/langhelpers.py:224: in __exit__
    raise exc_value.with_traceback(exc_tb)
.venv/lib/python3.12/site-packages/sqlalchemy/pool/impl.py:177: in _do_get
    return self._create_connection()
           ^^^^^^^^^^^^^^^^^^^^^^^^^
.venv/lib/python3.12/site-packages/sqlalchemy/pool/base.py:390: in _create_connection
    return _ConnectionRecord(self)
           ^^^^^^^^^^^^^^^^^^^^^^^
.venv/lib/python3.12/site-packages/sqlalchemy/pool/base.py:675: in __init__
    self.__connect()
.venv/lib/python3.12/site-packages/sqlalchemy/pool/base.py:901: in __connect
    with util.safe_reraise():
.venv/lib/python3.12/site-packages/sqlalchemy/util/langhelpers.py:224: in __exit__
    raise exc_value.with_traceback(exc_tb)
.venv/lib/python3.12/site-packages/sqlalchemy/pool/base.py:897: in __connect
    self.dbapi_connection = connection = pool._invoke_creator(self)
                                         ^^^^^^^^^^^^^^^^^^^^^^^^^^
.venv/lib/python3.12/site-packages/sqlalchemy/engine/create.py:646: in connect
    return dialect.connect(*cargs, **cparams)
           ^^^^^^^^^^^^^^^^^^^^^^^^^^^^^^^^^^
.venv/lib/python3.12/site-packages/sqlalchemy/engine/default.py:625: in connect
    return self.loaded_dbapi.connect(*cargs, **cparams)  # type: ignore[no-any-return]  # NOQA: E501
           ^^^^^^^^^^^^^^^^^^^^^^^^^^^^^^^^^^^^^^^^^^^^
.venv/lib/python3.12/site-packages/psycopg2/__init__.py:122: in connect
    conn = _connect(dsn, connection_factory=connection_factory, **kwasync)
           ^^^^^^^^^^^^^^^^^^^^^^^^^^^^^^^^^^^^^^^^^^^^^^^^^^^^^^^^^^^^^^^
E   sqlalchemy.exc.OperationalError: (psycopg2.OperationalError) connection to server at "localhost" (::1), port 5432 failed: Connection refused
E   	Is the server running on that host and accepting TCP/IP connections?
E   connection to server at "localhost" (127.0.0.1), port 5432 failed: Connection refused
E   	Is the server running on that host and accepting TCP/IP connections?
E   
E   (Background on this error at: https://sqlalche.me/e/20/e3q8)
___________ ERROR collecting tests/test_cct_clausulas_controller.py ____________
ImportError while importing test module '/workspaces/AUDITORIA360/tests/test_cct_clausulas_controller.py'.
Hint: make sure your test modules/packages have valid Python names.
Traceback:
/home/codespace/.python/current/lib/python3.12/importlib/__init__.py:90: in import_module
    return _bootstrap._gcd_import(name[level:], package, level)
           ^^^^^^^^^^^^^^^^^^^^^^^^^^^^^^^^^^^^^^^^^^^^^^^^^^^^
tests/test_cct_clausulas_controller.py:2: in <module>
    from src_legacy_backup.backend.controllers import cct_clausulas_controller
E   ModuleNotFoundError: No module named 'src_legacy_backup'
________________ ERROR collecting tests/test_cct_controller.py _________________
ImportError while importing test module '/workspaces/AUDITORIA360/tests/test_cct_controller.py'.
Hint: make sure your test modules/packages have valid Python names.
Traceback:
/home/codespace/.python/current/lib/python3.12/importlib/__init__.py:90: in import_module
    return _bootstrap._gcd_import(name[level:], package, level)
           ^^^^^^^^^^^^^^^^^^^^^^^^^^^^^^^^^^^^^^^^^^^^^^^^^^^^
tests/test_cct_controller.py:2: in <module>
    from src_legacy_backup.backend.controllers import cct_controller
E   ModuleNotFoundError: No module named 'src_legacy_backup'
__________________ ERROR collecting tests/test_cct_upload.py ___________________
ImportError while importing test module '/workspaces/AUDITORIA360/tests/test_cct_upload.py'.
Hint: make sure your test modules/packages have valid Python names.
Traceback:
/home/codespace/.python/current/lib/python3.12/importlib/__init__.py:90: in import_module
    return _bootstrap._gcd_import(name[level:], package, level)
           ^^^^^^^^^^^^^^^^^^^^^^^^^^^^^^^^^^^^^^^^^^^^^^^^^^^^
tests/test_cct_upload.py:5: in <module>
    from src_legacy_backup.api.routes.cct_routes import router as cct_router
E   ModuleNotFoundError: No module named 'src_legacy_backup'
__________ ERROR collecting tests/test_consultor_riscos_controller.py __________
ImportError while importing test module '/workspaces/AUDITORIA360/tests/test_consultor_riscos_controller.py'.
Hint: make sure your test modules/packages have valid Python names.
Traceback:
/home/codespace/.python/current/lib/python3.12/importlib/__init__.py:90: in import_module
    return _bootstrap._gcd_import(name[level:], package, level)
           ^^^^^^^^^^^^^^^^^^^^^^^^^^^^^^^^^^^^^^^^^^^^^^^^^^^^
tests/test_consultor_riscos_controller.py:2: in <module>
    from src_legacy_backup.backend.controllers import consultor_riscos_controller
E   ModuleNotFoundError: No module named 'src_legacy_backup'
____________ ERROR collecting tests/test_param_legais_controller.py ____________
ImportError while importing test module '/workspaces/AUDITORIA360/tests/test_param_legais_controller.py'.
Hint: make sure your test modules/packages have valid Python names.
Traceback:
/home/codespace/.python/current/lib/python3.12/importlib/__init__.py:90: in import_module
    return _bootstrap._gcd_import(name[level:], package, level)
           ^^^^^^^^^^^^^^^^^^^^^^^^^^^^^^^^^^^^^^^^^^^^^^^^^^^^
tests/test_param_legais_controller.py:3: in <module>
    from src_legacy_backup.backend.controllers import param_legais_controller
E   ModuleNotFoundError: No module named 'src_legacy_backup'
_______________ ERROR collecting tests/test_predicao_service.py ________________
ImportError while importing test module '/workspaces/AUDITORIA360/tests/test_predicao_service.py'.
Hint: make sure your test modules/packages have valid Python names.
Traceback:
/home/codespace/.python/current/lib/python3.12/importlib/__init__.py:90: in import_module
    return _bootstrap._gcd_import(name[level:], package, level)
           ^^^^^^^^^^^^^^^^^^^^^^^^^^^^^^^^^^^^^^^^^^^^^^^^^^^^
tests/test_predicao_service.py:2: in <module>
    from src_legacy_backup.backend.controllers import predicao_risco_controller
E   ModuleNotFoundError: No module named 'src_legacy_backup'
=========================== short test summary info ============================
ERROR portal_demandas/tests/test_api.py - sqlalchemy.exc.OperationalError: (p...
ERROR tests/test_cct_clausulas_controller.py
ERROR tests/test_cct_controller.py
ERROR tests/test_cct_upload.py
ERROR tests/test_consultor_riscos_controller.py
ERROR tests/test_param_legais_controller.py
ERROR tests/test_predicao_service.py
!!!!!!!!!!!!!!!!!!! Interrupted: 7 errors during collection !!!!!!!!!!!!!!!!!!!!
======================== 7 warnings, 7 errors in 5.86s =========================
